Traceback (most recent call last):
  File "/opt/homebrew/anaconda3/envs/pse-ml/lib/python3.10/site-packages/jupyter_cache/executors/utils.py", line 58, in single_nb_execution
    executenb(
  File "/opt/homebrew/anaconda3/envs/pse-ml/lib/python3.10/site-packages/nbclient/client.py", line 1305, in execute
    return NotebookClient(nb=nb, resources=resources, km=km, **kwargs).execute()
  File "/opt/homebrew/anaconda3/envs/pse-ml/lib/python3.10/site-packages/jupyter_core/utils/__init__.py", line 166, in wrapped
    return loop.run_until_complete(inner)
  File "/opt/homebrew/anaconda3/envs/pse-ml/lib/python3.10/asyncio/base_events.py", line 649, in run_until_complete
    return future.result()
  File "/opt/homebrew/anaconda3/envs/pse-ml/lib/python3.10/site-packages/nbclient/client.py", line 705, in async_execute
    await self.async_execute_cell(
  File "/opt/homebrew/anaconda3/envs/pse-ml/lib/python3.10/site-packages/nbclient/client.py", line 1058, in async_execute_cell
    await self._check_raise_for_error(cell, cell_index, exec_reply)
  File "/opt/homebrew/anaconda3/envs/pse-ml/lib/python3.10/site-packages/nbclient/client.py", line 914, in _check_raise_for_error
    raise CellExecutionError.from_cell_and_msg(cell, exec_reply_content)
nbclient.exceptions.CellExecutionError: An error occurred while executing the following cell:
------------------
from sklearn.datasets import make_classification

"""
There are some rules
(1) Number of informative, redundant and repeated features must sum to less than the number of total features.
(2) n_classes * n_clusters_per_class must be smaller or equal 2**n_informative
"""
separability = 0.7
X0, y0 = make_classification(n_samples=100, 
                           n_features=2, n_informative=1, n_redundant=0, 
                           n_repeated=0, 
                           n_classes=2, n_clusters_per_class=1, 
                           weights=None, flip_y=0.01, 
                           class_sep=separability, hypercube=True, 
                           shift=0.0, scale=1.0, shuffle=True, 
                           random_state=42)

fig, ax = plt.subplots(figsize=(10,10))
ax.scatter(X0[:,0], X0[:,1],c=y1, cmap="RdYlBu")
ax.set_title("Linear separable ?")
plt.show()
------------------


[0;31m---------------------------------------------------------------------------[0m
[0;31mNameError[0m                                 Traceback (most recent call last)
Cell [0;32mIn[3], line 19[0m
[1;32m      9[0m X0, y0 [38;5;241m=[39m make_classification(n_samples[38;5;241m=[39m[38;5;241m100[39m, 
[1;32m     10[0m                            n_features[38;5;241m=[39m[38;5;241m2[39m, n_informative[38;5;241m=[39m[38;5;241m1[39m, n_redundant[38;5;241m=[39m[38;5;241m0[39m, 
[1;32m     11[0m                            n_repeated[38;5;241m=[39m[38;5;241m0[39m, 
[0;32m   (...)[0m
[1;32m     15[0m                            shift[38;5;241m=[39m[38;5;241m0.0[39m, scale[38;5;241m=[39m[38;5;241m1.0[39m, shuffle[38;5;241m=[39m[38;5;28;01mTrue[39;00m, 
[1;32m     16[0m                            random_state[38;5;241m=[39m[38;5;241m42[39m)
[1;32m     18[0m fig, ax [38;5;241m=[39m plt[38;5;241m.[39msubplots(figsize[38;5;241m=[39m([38;5;241m10[39m,[38;5;241m10[39m))
[0;32m---> 19[0m ax[38;5;241m.[39mscatter(X0[:,[38;5;241m0[39m], X0[:,[38;5;241m1[39m],c[38;5;241m=[39m[43my1[49m, cmap[38;5;241m=[39m[38;5;124m"[39m[38;5;124mRdYlBu[39m[38;5;124m"[39m)
[1;32m     20[0m ax[38;5;241m.[39mset_title([38;5;124m"[39m[38;5;124mLinear separable ?[39m[38;5;124m"[39m)
[1;32m     21[0m plt[38;5;241m.[39mshow()

[0;31mNameError[0m: name 'y1' is not defined

